<?xml version="1.0" ?>
<robot name="softbot2" version="1.0">
  <material name="black">
    <color rgba="0.0 0.0 0.0 1.0"/>
  </material>
  <material name="dark">
    <color rgba="0.3 0.3 0.3 1.0"/>
  </material>
  <material name="light_black">
    <color rgba="0.4 0.4 0.4 1.0"/>
  </material>
  <material name="blue">
    <color rgba="0.0 0.0 0.8 1.0"/>
  </material>
  <material name="green">
    <color rgba="0.0 0.8 0.0 1.0"/>
  </material>
  <material name="grey">
    <color rgba="0.5 0.5 0.5 1.0"/>
  </material>
  <material name="orange">
    <color rgba="1.0 0.4235294117647059 0.0392156862745098 1.0"/>
  </material>
  <material name="brown">
    <color rgba="0.8705882352941177 0.8117647058823529 0.7647058823529411 1.0"/>
  </material>
  <material name="red">
    <color rgba="0.8 0.0 0.0 1.0"/>
  </material>
  <material name="white">
    <color rgba="1.0 1.0 1.0 1.0"/>
  </material>
  <material name="Yellow">
    <color rgba="1.0 1.0 0.0 1.0"/>
  </material>
  <material name="Orange">
    <color rgba="1.0 0.4 0.0 1.0"/>
  </material>
  <material name="Gray">
    <color rgba="1.0 0.4 0.0 1.0"/>
  </material>
  <gazebo reference="base_link">
    <material>Gazebo/Orange</material>
  </gazebo>
  <gazebo reference="base_link">
    <sensor name="base_link" type="contact">
      <update_rate>1000.0</update_rate>
      <always_on>true</always_on>
      <contact>
        <collision>base_footprint_fixed_joint_lump__base_link_collision_collision</collision>
      </contact>
      <plugin filename="libgazebo_ros_bumper.so" name="base_link_contact_sensor_plugin">
        <bumperTopicName>contact</bumperTopicName>
        <frameName>world</frameName>
      </plugin>
    </sensor>
  </gazebo>
  <gazebo reference="wheel_left_link">
    <mu1>0.1</mu1>
    <mu2>0.1</mu2>
    <kp>500000.0</kp>
    <kd>10.0</kd>
    <minDepth>0.001</minDepth>
    <maxVel>0.1</maxVel>
    <fdir1>1 0 0</fdir1>
    <material>Gazebo/Orange</material>
  </gazebo>
  <gazebo reference="wheel_right_link">
    <mu1>0.1</mu1>
    <mu2>0.1</mu2>
    <kp>500000.0</kp>
    <kd>10.0</kd>
    <minDepth>0.001</minDepth>
    <maxVel>0.01</maxVel>
    <fdir1>1 0 0</fdir1>
    <material>Gazebo/Orange</material>
  </gazebo>
  <gazebo reference="caster_back_right_link">
    <mu1>0.1</mu1>
    <mu2>0.1</mu2>
    <kp>1000000.0</kp>
    <kd>100.0</kd>
    <minDepth>0.001</minDepth>
    <maxVel>1.0</maxVel>
    <material>Gazebo/FlatBlack</material>
  </gazebo>
  <gazebo reference="caster_back_left_link">
    <mu1>0.1</mu1>
    <mu2>0.1</mu2>
    <kp>1000000.0</kp>
    <kd>100.0</kd>
    <minDepth>0.001</minDepth>
    <maxVel>1.0</maxVel>
    <material>Gazebo/FlatBlack</material>
  </gazebo>
  <gazebo reference="imu_link">
    <sensor name="imu" type="imu">
      <always_on>true</always_on>
      <visualize>True</visualize>
    </sensor>
    <material>Gazebo/Grey</material>
  </gazebo>
  <gazebo>
    <plugin filename="libgazebo_ros_diff_drive.so" name="turtlebot3_waffle_pi_controller">
      <commandTopic>cmd_vel</commandTopic>
      <odometryTopic>odom</odometryTopic>
      <odometryFrame>world</odometryFrame>
      <odometrySource>world</odometrySource>
      <publishOdomTF>true</publishOdomTF>
      <robotBaseFrame>base_footprint</robotBaseFrame>
      <publishWheelTF>false</publishWheelTF>
      <publishTf>true</publishTf>
      <publishWheelJointState>true</publishWheelJointState>
      <legacyMode>false</legacyMode>
      <updateRate>30</updateRate>
      <leftJoint>wheel_left_joint</leftJoint>
      <rightJoint>wheel_right_joint</rightJoint>
      <wheelSeparation>0.287</wheelSeparation>
      <wheelDiameter>0.066</wheelDiameter>
      <wheelAcceleration>1</wheelAcceleration>
      <wheelTorque>10</wheelTorque>
      <rosDebugLevel>na</rosDebugLevel>
    </plugin>
  </gazebo>
  <gazebo>
    <plugin filename="libgazebo_ros_imu.so" name="imu_plugin">
      <alwaysOn>true</alwaysOn>
      <bodyName>imu_link</bodyName>
      <frameName>imu_link</frameName>
      <topicName>imu</topicName>
      <serviceName>imu_service</serviceName>
      <gaussianNoise>0.0</gaussianNoise>
      <updateRate>200</updateRate>
      <imu>
        <noise>
          <type>gaussian</type>
          <rate>
            <mean>0.0</mean>
            <stddev>2e-4</stddev>
            <bias_mean>0.0000075</bias_mean>
            <bias_stddev>0.0000008</bias_stddev>
          </rate>
          <accel>
            <mean>0.0</mean>
            <stddev>1.7e-2</stddev>
            <bias_mean>0.1</bias_mean>
            <bias_stddev>0.001</bias_stddev>
          </accel>
        </noise>
      </imu>
    </plugin>
  </gazebo>
  <gazebo reference="base_scan">
    <material>Gazebo/FlatBlack</material>
    <sensor name="lds_lfcd_sensor" type="ray">
      <pose>0 0 0 0 0 0</pose>
      <visualize>False</visualize>
      <update_rate>5</update_rate>
      <ray>
        <scan>
          <horizontal>
            <samples>360</samples>
            <resolution>1</resolution>
            <min_angle>0.0</min_angle>
            <max_angle>6.28319</max_angle>
          </horizontal>
        </scan>
        <range>
          <min>0.120</min>
          <max>3.5</max>
          <resolution>0.015</resolution>
        </range>
        <noise>
          <type>gaussian</type>
          <mean>0.0</mean>
          <stddev>0.01</stddev>
        </noise>
      </ray>
      <plugin filename="libgazebo_ros_laser.so" name="gazebo_ros_lds_lfcd_controller">
        <topicName>scan</topicName>
        <frameName>base_scan</frameName>
      </plugin>
    </sensor>
  </gazebo>
  <link name="base_footprint"/>
  <joint name="base_joint" type="fixed">
    <origin xyz="0.0 0.0 0.01" rpy="0.0 0.0 0.0"/>
    <parent link="base_footprint"/>
    <child link="base_link"/>
  </joint>
  <link name="base_link">
    <inertial>
      <origin xyz="0.0 0.0 0.0" rpy="0.0 0.0 0.0"/>
      <mass value="1.3729096"/>
      <inertia ixx="0.0087002718" ixy="-4.7576583e-05" ixz="0.00011160499" iyy="0.0086195418" iyz="-3.5422299e-06" izz="0.014612727"/>
    </inertial>
    <visual>
      <origin xyz="-0.064 0.0 0.0" rpy="0.0 0.0 0.0"/>
      <geometry>
        <mesh filename="package://turtlebot3_description/meshes/bases/waffle_pi_base.stl" scale="0.001 0.001 0.001"/>
      </geometry>
      <material name="light_black"/>
    </visual>
    <collision name="base_link_collision">
      <origin xyz="-0.064 0.0 0.047" rpy="0.0 0.0 0.0"/>
      <geometry>
        <box size="0.3 0.3 0.094"/>
      </geometry>
    </collision>
  </link>
  <joint name="wheel_left_joint" type="continuous">
    <origin xyz="0.0 0.144 0.023" rpy="-1.57 0.0 0.0"/>
    <axis xyz="0.0 0.0 1.0"/>
    <parent link="base_link"/>
    <child link="wheel_left_link"/>
  </joint>
  <link name="wheel_left_link">
    <inertial>
      <origin xyz="0.0 0.0 0.0" rpy="0 0 0"/>
      <mass value="0.2849894"/>
      <inertia ixx="0.001117558" ixy="-4.2369783e-11" ixz="-5.9381719e-09" iyy="0.0011192413" iyz="-1.4400107e-11" izz="0.0020712558"/>
    </inertial>
    <visual>
      <origin xyz="0.0 0.0 0.0" rpy="1.57 0.0 0.0"/>
      <geometry>
        <mesh filename="package://turtlebot3_description/meshes/wheels/left_tire.stl" scale="0.001 0.001 0.001"/>
      </geometry>
      <material name="black"/>
    </visual>
    <collision>
      <origin xyz="0.0 0.0 0.0" rpy="0.0 0.0 0.0"/>
      <geometry>
        <cylinder radius="0.033" length="0.018"/>
      </geometry>
    </collision>
  </link>
  <joint name="wheel_right_joint" type="continuous">
    <origin xyz="0.0 -0.144 0.023" rpy="-1.57 0.0 0.0"/>
    <axis xyz="0.0 0.0 1.0"/>
    <parent link="base_link"/>
    <child link="wheel_right_link"/>
  </joint>
  <link name="wheel_right_link">
    <inertial>
      <origin xyz="0.0 0.0 0.0" rpy="0 0 0"/>
      <mass value="0.2849894"/>
      <inertia ixx="0.001117558" ixy="-4.2369783e-11" ixz="-5.9381719e-09" iyy="0.0011192413" iyz="-1.4400107e-11" izz="0.0020712558"/>
    </inertial>
    <visual>
      <origin xyz="0.0 0.0 0.0" rpy="1.57 0.0 0.0"/>
      <geometry>
        <mesh filename="package://turtlebot3_description/meshes/wheels/right_tire.stl" scale="0.001 0.001 0.001"/>
      </geometry>
      <material name="black"/>
    </visual>
    <collision>
      <origin xyz="0.0 0.0 0.0" rpy="0.0 0.0 0.0"/>
      <geometry>
        <cylinder radius="0.033" length="0.018"/>
      </geometry>
    </collision>
  </link>
  <joint name="caster_back_right_joint" type="fixed">
    <origin xyz="-0.177 -0.064 -0.004" rpy="-1.57 0.0 0.0"/>
    <parent link="base_link"/>
    <child link="caster_back_right_link"/>
  </joint>
  <link name="caster_back_right_link">
    <inertial>
      <origin xyz="0.0 0.0 0.0" rpy="0 0 0"/>
      <mass value="0.005"/>
      <inertia ixx="0.001" ixy="0.0" ixz="0.0" iyy="0.001" iyz="0.0" izz="0.001"/>
    </inertial>
    <collision>
      <origin xyz="0.0 0.001 0.0" rpy="0.0 0.0 0.0"/>
      <geometry>
        <box size="0.03 0.009 0.02"/>
      </geometry>
    </collision>
  </link>
  <joint name="caster_back_left_joint" type="fixed">
    <origin xyz="-0.177 0.064 -0.004" rpy="-1.57 0.0 0.0"/>
    <parent link="base_link"/>
    <child link="caster_back_left_link"/>
  </joint>
  <link name="caster_back_left_link">
    <inertial>
      <origin xyz="0.0 0.0 0.0" rpy="0 0 0"/>
      <mass value="0.005"/>
      <inertia ixx="0.001" ixy="0.0" ixz="0.0" iyy="0.001" iyz="0.0" izz="0.001"/>
    </inertial>
    <collision>
      <origin xyz="0.0 0.001 0.0" rpy="0.0 0.0 0.0"/>
      <geometry>
        <box size="0.03 0.009 0.02"/>
      </geometry>
    </collision>
  </link>
  <joint name="imu_joint" type="fixed">
    <origin xyz="0.0 0.0 0.068" rpy="0.0 0.0 0.0"/>
    <parent link="base_link"/>
    <child link="imu_link"/>
  </joint>
  <link name="imu_link"/>
  <link name="platform_support_leg1_link">
    <visual>
      <origin xyz="0.0 0.0 -0.1" rpy="0.0 0.0 0.0"/>
      <geometry>
        <cylinder radius="0.004" length="0.2"/>
      </geometry>
      <material name="grey"/>
    </visual>
  </link>
  <joint name="base_link_to_platform_support_leg1_link" type="fixed">
    <origin xyz="-0.114 0.0 0.222" rpy="0.0 0.0 0.0"/>
    <parent link="base_link"/>
    <child link="platform_support_leg1_link"/>
  </joint>
  <link name="platform_support_leg2_link">
    <visual>
      <origin xyz="0.0 0.0 -0.1" rpy="0.0 0.0 0.0"/>
      <geometry>
        <cylinder radius="0.004" length="0.2"/>
      </geometry>
      <material name="grey"/>
    </visual>
  </link>
  <joint name="base_link_to_platform_support_leg2_link" type="fixed">
    <origin xyz="-0.114 -0.1 0.222" rpy="0.0 0.0 0.0"/>
    <parent link="base_link"/>
    <child link="platform_support_leg2_link"/>
  </joint>
  <link name="platform_support_leg3_link">
    <visual>
      <origin xyz="0.0 0.0 -0.1" rpy="0.0 0.0 0.0"/>
      <geometry>
        <cylinder radius="0.004" length="0.2"/>
      </geometry>
      <material name="grey"/>
    </visual>
  </link>
  <joint name="base_link_to_platform_support_leg3_link" type="fixed">
    <origin xyz="-0.014 0.0 0.222" rpy="0.0 0.0 0.0"/>
    <parent link="base_link"/>
    <child link="platform_support_leg3_link"/>
  </joint>
  <link name="platform_support_leg4_link">
    <visual>
      <origin xyz="0.0 0.0 -0.1" rpy="0.0 0.0 0.0"/>
      <geometry>
        <cylinder radius="0.004" length="0.2"/>
      </geometry>
      <material name="grey"/>
    </visual>
  </link>
  <joint name="base_link_to_platform_support_leg4_link" type="fixed">
    <origin xyz="-0.014 -0.1 0.222" rpy="0.0 0.0 0.0"/>
    <parent link="base_link"/>
    <child link="platform_support_leg4_link"/>
  </joint>
  <link name="lidar3d_plate_link">
    <visual>
      <origin xyz="0.0 0.0 0.0" rpy="0.0 0.0 0.0"/>
      <geometry>
        <box size="0.14 0.14 0.005"/>
      </geometry>
      <material name="grey"/>
    </visual>
  </link>
  <joint name="platform_support_leg1_link_to_lidar3d_plate_link" type="fixed">
    <origin xyz="0.05 -0.05 0.0" rpy="0.0 0.0 0.0"/>
    <parent link="platform_support_leg1_link"/>
    <child link="lidar3d_plate_link"/>
  </joint>
  <joint name="lidar3d_base_mount_joint" type="fixed">
    <origin xyz="0.0 0.0 0.0" rpy="0.0 0.0 0.0"/>
    <parent link="lidar3d_plate_link"/>
    <child link="lidar3d_base_link"/>
  </joint>
  <link name="lidar3d_base_link">
    <inertial>
      <origin xyz="0.0 0.0 0.03585" rpy="0 0 0"/>
      <mass value="0.083"/>
      <inertia ixx="0.000908059425" ixy="0.0" ixz="0.0" iyy="0.000908059425" iyz="0.0" izz="0.0011049624"/>
    </inertial>
    <visual>
      <geometry>
        <mesh filename="package://softbot_description/meshes/vlp-16/VLP16_base_1_blue.dae"/>
      </geometry>
    </visual>
    <visual>
      <geometry>
        <mesh filename="package://softbot_description/meshes/vlp-16/VLP16_base_2_blue.dae"/>
      </geometry>
    </visual>
    <collision>
      <origin xyz="0.0 0.0 0.03585" rpy="0.0 0.0 0.0"/>
      <geometry>
        <cylinder radius="0.0516" length="0.0717"/>
      </geometry>
    </collision>
  </link>
  <joint name="lidar3d_base_scan_joint" type="fixed">
    <origin xyz="0.0 0.0 0.0377" rpy="0.0 0.0 0.0"/>
    <parent link="lidar3d_base_link"/>
    <child link="lidar3d"/>
  </joint>
  <link name="lidar3d">
    <inertial>
      <origin xyz="0.0 0.0 0.0" rpy="0 0 0"/>
      <mass value="0.01"/>
      <inertia ixx="1e-07" ixy="0.0" ixz="0.0" iyy="1e-07" iyz="0.0" izz="1e-07"/>
    </inertial>
    <visual>
      <origin xyz="0.0 0.0 -0.0377" rpy="0 0 0"/>
      <geometry>
        <mesh filename="package://velodyne_description/meshes/VLP16_scan.dae"/>
      </geometry>
    </visual>
  </link>
  <gazebo reference="lidar3d">
    <sensor name="lidar3d-VLP16" type="ray">
      <pose>0 0 0 0 0 0</pose>
      <visualize>false</visualize>
      <update_rate>10</update_rate>
      <ray>
        <scan>
          <horizontal>
            <samples>1875</samples>
            <resolution>1</resolution>
            <min_angle>-3.141592653589793</min_angle>
            <max_angle>3.141592653589793</max_angle>
          </horizontal>
          <vertical>
            <samples>16</samples>
            <resolution>1</resolution>
            <min_angle>-0.2617993877991494</min_angle>
            <max_angle> 0.2617993877991494</max_angle>
          </vertical>
        </scan>
        <range>
          <min>0.3</min>
          <max>131.0</max>
          <resolution>0.001</resolution>
        </range>
        <noise>
          <type>gaussian</type>
          <mean>0.0</mean>
          <stddev>0.0</stddev>
        </noise>
      </ray>
      <plugin filename="libgazebo_ros_velodyne_laser.so" name="gazebo_ros_laser_controller">
        <topicName>/lidar3d/points</topicName>
        <frameName>lidar3d</frameName>
        <organize_cloud>False</organize_cloud>
        <min_range>0.9</min_range>
        <max_range>130.0</max_range>
        <gaussianNoise>0.008</gaussianNoise>
      </plugin>
    </sensor>
  </gazebo>
  <link name="body_camera_support_link"/>
  <joint name="platform_support_leg3_link_to_body_camera_support_link" type="fixed">
    <origin xyz="0.02 -0.05 -0.13" rpy="0.01 -0.35 0.05"/>
    <parent link="platform_support_leg3_link"/>
    <child link="body_camera_support_link"/>
  </joint>
  <joint name="body_camera_joint" type="fixed">
    <origin xyz="0.02 0.07 0.015" rpy="0.0 0.0 0.0"/>
    <parent link="body_camera_support_link"/>
    <child link="body_camera_link"/>
  </joint>
  <link name="body_camera_link">
    <inertial>
      <origin xyz="0.0 0.0 0.0" rpy="0 0 0"/>
      <mass value="0.00564"/>
      <inertia ixx="0.003881243" ixy="0.0" ixz="0.0" iyy="0.00049894" iyz="0.0" izz="0.003879257"/>
    </inertial>
    <visual>
      <origin xyz="-0.03 -0.06 0.0" rpy="3.141592653589793 0.0 1.5707963267948966"/>
      <geometry>
        <mesh filename="package://softbot_description/meshes/astra2/astra2_red.dae" scale="1.0 1.0 1.0"/>
      </geometry>
    </visual>
    <collision>
      <origin xyz="-0.01 -0.06 0.0" rpy="0.0 0.0 0.0"/>
      <geometry>
        <box size="0.04 0.165 0.03"/>
      </geometry>
    </collision>
  </link>
  <gazebo reference="body_camera_link">
    <selfCollide>false</selfCollide>
  </gazebo>
  <joint name="body_camera_rgb_joint" type="fixed">
    <origin xyz="0.00012269771519343576 -0.044719692006212605 -0.003362822947788794" rpy="0.0051473990343029645 0.0036312250447137736 -0.00042017158966324895"/>
    <parent link="body_camera_link"/>
    <child link="body_camera_rgb_frame"/>
  </joint>
  <link name="body_camera_rgb_frame"/>
  <joint name="body_camera_rgb_optical_joint" type="fixed">
    <origin xyz="0.0 0.0 0.0" rpy="-1.5707963267948966 0.0 -1.5707963267948966"/>
    <parent link="body_camera_rgb_frame"/>
    <child link="body_camera_rgb_optical_frame"/>
  </joint>
  <link name="body_camera_rgb_optical_frame"/>
  <joint name="body_camera_depth_joint" type="fixed">
    <origin xyz="0.0 -0.02 0.0" rpy="0.0 0.0 0.0"/>
    <parent link="body_camera_link"/>
    <child link="body_camera_depth_frame"/>
  </joint>
  <link name="body_camera_depth_frame"/>
  <joint name="body_camera_depth_optical_joint" type="fixed">
    <origin xyz="0.0 0.0 0.0" rpy="-1.5707963267948966 0.0 -1.5707963267948966"/>
    <parent link="body_camera_depth_frame"/>
    <child link="body_camera_depth_optical_frame"/>
  </joint>
  <link name="body_camera_depth_optical_frame"/>
  <gazebo reference="body_camera_depth_frame">
    <sensor name="camera" type="depth">
      <always_on>true</always_on>
      <update_rate>10.0</update_rate>
      <camera>
        <horizontal_fov>1.0471975511965976</horizontal_fov>
        <image>
          <format>B8G8R8</format>
          <width>640</width>
          <height>480</height>
        </image>
        <clip>
          <near>0.10</near>
          <far>8.0</far>
        </clip>
      </camera>
      <plugin filename="libgazebo_ros_openni_kinect.so" name="body_camera_depth_camera_controller">
        <cameraName>body_camera</cameraName>
        <alwaysOn>true</alwaysOn>
        <updateRate>10.0</updateRate>
        <imageTopicName>null</imageTopicName>
        <cameraInfoTopicName>null/camera_info</cameraInfoTopicName>
        <depthImageTopicName>depth/image_raw</depthImageTopicName>
        <pointCloudTopicName>depth/points</pointCloudTopicName>
        <depthImageCameraInfoTopicName>depth/camera_info</depthImageCameraInfoTopicName>
        <frameName>body_camera_depth_optical_frame</frameName>
        <baseline>0.1</baseline>
        <distortion_k1>0.0</distortion_k1>
        <distortion_k2>0.0</distortion_k2>
        <distortion_k3>0.0</distortion_k3>
        <distortion_t1>0.0</distortion_t1>
        <distortion_t2>0.0</distortion_t2>
        <pointCloudCutoff>0.4</pointCloudCutoff>
      </plugin>
    </sensor>
  </gazebo>
  <gazebo reference="body_camera_rgb_frame">
    <sensor name="camera" type="camera">
      <update_rate>30.0</update_rate>
      <camera>
        <horizontal_fov>1.0471975511965976</horizontal_fov>
        <image>
          <format>B8G8R8</format>
          <width>1200</width>
          <height>800</height>
        </image>
        <clip>
          <near>0.10</near>
          <far>8.0</far>
        </clip>
      </camera>
      <plugin filename="libgazebo_ros_camera.so" name="body_camera_rgb_camera_controller">
        <cameraName>body_camera</cameraName>
        <alwaysOn>true</alwaysOn>
        <updateRate>0</updateRate>
        <imageTopicName>rgb/image_raw</imageTopicName>
        <cameraInfoTopicName>rgb/camera_info</cameraInfoTopicName>
        <frameName>body_camera_rgb_optical_frame</frameName>
        <baseline>0.0</baseline>
        <distortion_k1>0.0</distortion_k1>
        <distortion_k2>0.0</distortion_k2>
        <distortion_k3>0.0</distortion_k3>
        <distortion_t1>0.0</distortion_t1>
        <distortion_t2>0.0</distortion_t2>
      </plugin>
    </sensor>
  </gazebo>
  <link name="hand_camera_support_link"/>
  <joint name="end_effector_link_to_hand_camera_support_link" type="fixed">
    <origin xyz="-0.08 0.0 0.04" rpy="0.0 0.0 0.0"/>
    <parent link="end_effector_link"/>
    <child link="hand_camera_support_link"/>
  </joint>
  <joint name="hand_camera_joint" type="fixed">
    <origin xyz="0.02 0.07 0.015" rpy="0.0 0.0 0.0"/>
    <parent link="hand_camera_support_link"/>
    <child link="hand_camera_link"/>
  </joint>
  <link name="hand_camera_link">
    <inertial>
      <origin xyz="0.0 0.0 0.0" rpy="0 0 0"/>
      <mass value="0.00564"/>
      <inertia ixx="0.003881243" ixy="0.0" ixz="0.0" iyy="0.00049894" iyz="0.0" izz="0.003879257"/>
    </inertial>
    <visual>
      <origin xyz="-0.03 -0.06 0.0" rpy="3.141592653589793 0.0 1.5707963267948966"/>
      <geometry>
        <mesh filename="package://softbot_description/meshes/astra2/astra2_green.dae" scale="1.0 1.0 1.0"/>
      </geometry>
    </visual>
    <collision>
      <origin xyz="-0.01 -0.06 0.0" rpy="0.0 0.0 0.0"/>
      <geometry>
        <box size="0.04 0.165 0.03"/>
      </geometry>
    </collision>
  </link>
  <gazebo reference="hand_camera_link">
    <selfCollide>false</selfCollide>
  </gazebo>
  <joint name="hand_camera_rgb_joint" type="fixed">
    <origin xyz="0.0 -0.045 0.0" rpy="0.0 0.0 0.0"/>
    <parent link="hand_camera_link"/>
    <child link="hand_camera_rgb_frame"/>
  </joint>
  <link name="hand_camera_rgb_frame"/>
  <joint name="hand_camera_rgb_optical_joint" type="fixed">
    <origin xyz="0.0 0.0 0.0" rpy="-1.5707963267948966 0.0 -1.5707963267948966"/>
    <parent link="hand_camera_rgb_frame"/>
    <child link="hand_camera_rgb_optical_frame"/>
  </joint>
  <link name="hand_camera_rgb_optical_frame"/>
  <joint name="hand_camera_depth_joint" type="fixed">
    <origin xyz="0.0 -0.02 0.0" rpy="0.0 0.0 0.0"/>
    <parent link="hand_camera_link"/>
    <child link="hand_camera_depth_frame"/>
  </joint>
  <link name="hand_camera_depth_frame"/>
  <joint name="hand_camera_depth_optical_joint" type="fixed">
    <origin xyz="0.0 0.0 0.0" rpy="-1.5707963267948966 0.0 -1.5707963267948966"/>
    <parent link="hand_camera_depth_frame"/>
    <child link="hand_camera_depth_optical_frame"/>
  </joint>
  <link name="hand_camera_depth_optical_frame"/>
  <gazebo reference="hand_camera_depth_frame">
    <sensor name="camera" type="depth">
      <always_on>true</always_on>
      <update_rate>10.0</update_rate>
      <camera>
        <horizontal_fov>1.0471975511965976</horizontal_fov>
        <image>
          <format>B8G8R8</format>
          <width>640</width>
          <height>480</height>
        </image>
        <clip>
          <near>0.10</near>
          <far>8.0</far>
        </clip>
      </camera>
      <plugin filename="libgazebo_ros_openni_kinect.so" name="hand_camera_depth_camera_controller">
        <cameraName>hand_camera</cameraName>
        <alwaysOn>true</alwaysOn>
        <updateRate>10.0</updateRate>
        <imageTopicName>null</imageTopicName>
        <cameraInfoTopicName>null/camera_info</cameraInfoTopicName>
        <depthImageTopicName>depth/image_raw</depthImageTopicName>
        <pointCloudTopicName>depth/points</pointCloudTopicName>
        <depthImageCameraInfoTopicName>depth/camera_info</depthImageCameraInfoTopicName>
        <frameName>hand_camera_depth_optical_frame</frameName>
        <baseline>0.1</baseline>
        <distortion_k1>0.0</distortion_k1>
        <distortion_k2>0.0</distortion_k2>
        <distortion_k3>0.0</distortion_k3>
        <distortion_t1>0.0</distortion_t1>
        <distortion_t2>0.0</distortion_t2>
        <pointCloudCutoff>0.4</pointCloudCutoff>
      </plugin>
    </sensor>
  </gazebo>
  <gazebo reference="hand_camera_rgb_frame">
    <sensor name="camera" type="camera">
      <update_rate>30.0</update_rate>
      <camera>
        <horizontal_fov>1.0471975511965976</horizontal_fov>
        <image>
          <format>B8G8R8</format>
          <width>1200</width>
          <height>800</height>
        </image>
        <clip>
          <near>0.10</near>
          <far>8.0</far>
        </clip>
      </camera>
      <plugin filename="libgazebo_ros_camera.so" name="hand_camera_rgb_camera_controller">
        <cameraName>hand_camera</cameraName>
        <alwaysOn>true</alwaysOn>
        <updateRate>0</updateRate>
        <imageTopicName>rgb/image_raw</imageTopicName>
        <cameraInfoTopicName>rgb/camera_info</cameraInfoTopicName>
        <frameName>hand_camera_rgb_optical_frame</frameName>
        <baseline>0.0</baseline>
        <distortion_k1>0.0</distortion_k1>
        <distortion_k2>0.0</distortion_k2>
        <distortion_k3>0.0</distortion_k3>
        <distortion_t1>0.0</distortion_t1>
        <distortion_t2>0.0</distortion_t2>
      </plugin>
    </sensor>
  </gazebo>
  <gazebo reference="end_effector_link">
    <material>Gazebo/Red</material>
  </gazebo>
  <gazebo>
    <plugin filename="libgazebo_ros_control.so" name="gazebo_ros_control">
      <controlPeriod>0.001</controlPeriod>
      <robotSimType>gazebo_ros_control/DefaultRobotHWSim</robotSimType>
      <legacyModeNS>true</legacyModeNS>
    </plugin>
  </gazebo>
  <gazebo>
    <plugin filename="libroboticsgroup_gazebo_mimic_joint_plugin.so" name="gazebo_gripper_ros_control">
      <joint>gripper</joint>
      <mimicJoint>gripper_sub</mimicJoint>
      <multiplier>1.0</multiplier>
      <offset>0.0</offset>
      <hasPID>/gazebo_ros_control/pid_gains/gripper_sub</hasPID>
    </plugin>
  </gazebo>
  <transmission name="tran1">
    <type>transmission_interface/SimpleTransmission</type>
    <joint name="joint1">
      <hardwareInterface>hardware_interface/PositionJointInterface</hardwareInterface>
    </joint>
    <actuator name="motor1">
      <mechanicalReduction>1.0</mechanicalReduction>
    </actuator>
  </transmission>
  <transmission name="tran2">
    <type>transmission_interface/SimpleTransmission</type>
    <joint name="joint2">
      <hardwareInterface>hardware_interface/PositionJointInterface</hardwareInterface>
    </joint>
    <actuator name="motor2">
      <mechanicalReduction>1.0</mechanicalReduction>
    </actuator>
  </transmission>
  <transmission name="tran3">
    <type>transmission_interface/SimpleTransmission</type>
    <joint name="joint3">
      <hardwareInterface>hardware_interface/PositionJointInterface</hardwareInterface>
    </joint>
    <actuator name="motor3">
      <mechanicalReduction>1.0</mechanicalReduction>
    </actuator>
  </transmission>
  <transmission name="tran4">
    <type>transmission_interface/SimpleTransmission</type>
    <joint name="joint4">
      <hardwareInterface>hardware_interface/PositionJointInterface</hardwareInterface>
    </joint>
    <actuator name="motor4">
      <mechanicalReduction>1.0</mechanicalReduction>
    </actuator>
  </transmission>
  <transmission name="tran5">
    <type>transmission_interface/SimpleTransmission</type>
    <joint name="gripper">
      <hardwareInterface>hardware_interface/EffortJointInterface</hardwareInterface>
    </joint>
    <actuator name="motor5">
      <mechanicalReduction>1.0</mechanicalReduction>
    </actuator>
  </transmission>
  <transmission name="tran6">
    <type>transmission_interface/SimpleTransmission</type>
    <joint name="gripper_sub">
      <hardwareInterface>hardware_interface/EffortJointInterface</hardwareInterface>
    </joint>
    <actuator name="motor6">
      <mechanicalReduction>1.0</mechanicalReduction>
    </actuator>
  </transmission>
  <material name="light_grey">
    <color rgba="0.7 0.7 0.7 1.0"/>
  </material>
  <link name="link1">
    <inertial>
      <origin xyz="0.00030876154 0.0 -0.00012176461" rpy="0 0 0"/>
      <mass value="0.079119962"/>
      <inertia ixx="1.2505234e-05" ixy="0.0" ixz="-1.7855208e-07" iyy="2.1898364e-05" iyz="0.0" izz="1.9267361e-05"/>
    </inertial>
    <visual>
      <origin xyz="0.0 0.0 0.0" rpy="0.0 0.0 0.0"/>
      <geometry>
        <mesh filename="package://turtlebot3_manipulation_description/meshes/chain_link1.stl" scale="0.001 0.001 0.001"/>
      </geometry>
      <material name="light_grey"/>
    </visual>
    <collision>
      <origin xyz="0.0 0.0 0.0" rpy="0.0 0.0 0.0"/>
      <geometry>
        <mesh filename="package://turtlebot3_manipulation_description/meshes/chain_link1.stl" scale="0.001 0.001 0.001"/>
      </geometry>
    </collision>
  </link>
  <joint name="joint1" type="revolute">
    <origin xyz="0.012 0.0 0.017" rpy="0.0 0.0 0.0"/>
    <axis xyz="0.0 0.0 1.0"/>
    <parent link="link1"/>
    <child link="link2"/>
    <limit effort="1.0" lower="-2.827433388230814" upper="2.827433388230814" velocity="4.8"/>
  </joint>
  <link name="link2">
    <inertial>
      <origin xyz="-0.0003018487 0.00054043684 0.047433463999999995" rpy="0 0 0"/>
      <mass value="0.098406837"/>
      <inertia ixx="3.4543422e-05" ixy="-1.6031095e-08" ixz="-3.8375155e-07" iyy="3.2689329e-05" iyz="2.8511935e-08" izz="1.885032e-05"/>
    </inertial>
    <visual>
      <origin xyz="0.0 0.0 0.018" rpy="0.0 0.0 0.0"/>
      <geometry>
        <mesh filename="package://turtlebot3_manipulation_description/meshes/chain_link2.stl" scale="0.001 0.001 0.001"/>
      </geometry>
      <material name="light_grey"/>
    </visual>
    <collision>
      <origin xyz="0.0 0.0 0.018" rpy="0.0 0.0 0.0"/>
      <geometry>
        <mesh filename="package://turtlebot3_manipulation_description/meshes/chain_link2.stl" scale="0.001 0.001 0.001"/>
      </geometry>
    </collision>
  </link>
  <joint name="joint2" type="revolute">
    <origin xyz="0.0 0.0 0.058" rpy="0.0 0.0 0.0"/>
    <axis xyz="0.0 1.0 0.0"/>
    <parent link="link2"/>
    <child link="link3"/>
    <limit effort="1.0" lower="-1.790707812546182" upper="1.5707963267948966" velocity="4.8"/>
  </joint>
  <link name="link3">
    <inertial>
      <origin xyz="0.010308393 0.00037743363 0.10170197" rpy="0 0 0"/>
      <mass value="0.13850917"/>
      <inertia ixx="0.00033055381" ixy="-9.7940978e-08" ixz="-3.8505711e-05" iyy="0.00034290447" iyz="-1.5717516e-06" izz="6.0346498e-05"/>
    </inertial>
    <visual>
      <origin xyz="0.0 0.0 0.0" rpy="0.0 0.0 0.0"/>
      <geometry>
        <mesh filename="package://turtlebot3_manipulation_description/meshes/chain_link3.stl" scale="0.001 0.001 0.001"/>
      </geometry>
      <material name="light_grey"/>
    </visual>
    <collision>
      <origin xyz="0.0 0.0 0.0" rpy="0.0 0.0 0.0"/>
      <geometry>
        <mesh filename="package://turtlebot3_manipulation_description/meshes/chain_link3.stl" scale="0.001 0.001 0.001"/>
      </geometry>
    </collision>
  </link>
  <joint name="joint3" type="revolute">
    <origin xyz="0.024 0.0 0.128" rpy="0.0 0.0 0.0"/>
    <axis xyz="0.0 1.0 0.0"/>
    <parent link="link3"/>
    <child link="link4"/>
    <limit effort="1.0" lower="-0.9424777960769379" upper="1.382300767579509" velocity="4.8"/>
  </joint>
  <link name="link4">
    <inertial>
      <origin xyz="0.09090959 0.00038929816 0.00022413279" rpy="0 0 0"/>
      <mass value="0.13274562"/>
      <inertia ixx="3.0654178e-05" ixy="-1.2764155e-06" ixz="-2.6874417e-07" iyy="0.00024230292" iyz="1.155955e-08" izz="0.00025155057"/>
    </inertial>
    <visual>
      <origin xyz="0.0 0.0 0.0" rpy="0.0 0.0 0.0"/>
      <geometry>
        <mesh filename="package://turtlebot3_manipulation_description/meshes/chain_link4.stl" scale="0.001 0.001 0.001"/>
      </geometry>
      <material name="light_grey"/>
    </visual>
    <collision>
      <origin xyz="0.0 0.0 0.0" rpy="0.0 0.0 0.0"/>
      <geometry>
        <mesh filename="package://turtlebot3_manipulation_description/meshes/chain_link4.stl" scale="0.001 0.001 0.001"/>
      </geometry>
    </collision>
  </link>
  <joint name="joint4" type="revolute">
    <origin xyz="0.124 0.0 0.0" rpy="0.0 0.0 0.0"/>
    <axis xyz="0.0 1.0 0.0"/>
    <parent link="link4"/>
    <child link="link5"/>
    <limit effort="1.0" lower="-1.790707812546182" upper="2.0420352248333655" velocity="4.8"/>
  </joint>
  <link name="link5">
    <inertial>
      <origin xyz="0.044206755 3.6839985e-07 0.0089142216" rpy="0 0 0"/>
      <mass value="0.001"/>
      <inertia ixx="0.001" ixy="0.0" ixz="0.0" iyy="0.001" iyz="0.0" izz="0.001"/>
    </inertial>
    <visual>
      <origin xyz="0.0 0.0 0.0" rpy="0.0 0.0 0.0"/>
      <geometry>
        <mesh filename="package://turtlebot3_manipulation_description/meshes/chain_link5.stl" scale="0.001 0.001 0.001"/>
      </geometry>
      <material name="light_grey"/>
    </visual>
    <collision>
      <origin xyz="0.0 0.0 0.0" rpy="0.0 0.0 0.0"/>
      <geometry>
        <mesh filename="package://turtlebot3_manipulation_description/meshes/chain_link5.stl" scale="0.001 0.001 0.001"/>
      </geometry>
    </collision>
  </link>
  <link name="gripper_link">
    <inertial>
      <origin xyz="0.0 0.0 0.0" rpy="0 0 0"/>
      <mass value="0.001"/>
      <inertia ixx="0.001" ixy="0.0" ixz="0.0" iyy="0.001" iyz="0.0" izz="0.001"/>
    </inertial>
    <visual>
      <origin xyz="0.0 0.0 0.0" rpy="0.0 0.0 0.0"/>
      <geometry>
        <mesh filename="package://turtlebot3_manipulation_description/meshes/chain_link_grip_l.stl" scale="0.001 0.001 0.001"/>
      </geometry>
      <material name="light_grey"/>
    </visual>
    <collision>
      <origin xyz="0.0 0.0 0.0" rpy="0.0 0.0 0.0"/>
      <geometry>
        <mesh filename="package://turtlebot3_manipulation_description/meshes/chain_link_grip_l.stl" scale="0.001 0.001 0.001"/>
      </geometry>
    </collision>
  </link>
  <joint name="gripper" type="prismatic">
    <origin xyz="0.0817 0.021 0.0" rpy="0.0 0.0 0.0"/>
    <axis xyz="0.0 1.0 0.0"/>
    <parent link="link5"/>
    <child link="gripper_link"/>
    <limit effort="1.0" lower="-0.01" upper="0.019" velocity="4.8"/>
  </joint>
  <link name="gripper_link_sub">
    <inertial>
      <origin xyz="0.0 0.0 0.0" rpy="0 0 0"/>
      <mass value="0.001"/>
      <inertia ixx="0.001" ixy="0.0" ixz="0.0" iyy="0.001" iyz="0.0" izz="0.001"/>
    </inertial>
    <visual>
      <origin xyz="0.0 -0.0 0.0" rpy="0.0 0.0 0.0"/>
      <geometry>
        <mesh filename="package://turtlebot3_manipulation_description/meshes/chain_link_grip_r.stl" scale="0.001 0.001 0.001"/>
      </geometry>
      <material name="light_grey"/>
    </visual>
    <collision>
      <origin xyz="0.0 -0.0 0.0" rpy="0.0 0.0 0.0"/>
      <geometry>
        <mesh filename="package://turtlebot3_manipulation_description/meshes/chain_link_grip_r.stl" scale="0.001 0.001 0.001"/>
      </geometry>
    </collision>
  </link>
  <joint name="gripper_sub" type="prismatic">
    <origin xyz="0.0817 -0.021 0.0" rpy="0.0 0.0 0.0"/>
    <axis xyz="0.0 -1.0 0.0"/>
    <parent link="link5"/>
    <child link="gripper_link_sub"/>
    <limit effort="1.0" lower="-0.01" upper="0.019" velocity="4.8"/>
    <mimic joint="gripper" multiplier="1.0"/>
  </joint>
  <joint name="end_effector_joint" type="fixed">
    <origin xyz="0.126 0.0 0.0" rpy="0.0 0.0 0.0"/>
    <parent link="link5"/>
    <child link="end_effector_link"/>
  </joint>
  <link name="end_effector_link">
    <inertial>
      <origin xyz="0.0 0.0 0.0" rpy="0 0 0"/>
      <mass value="0.001"/>
      <inertia ixx="0.001" ixy="0.0" ixz="0.0" iyy="0.001" iyz="0.0" izz="0.001"/>
    </inertial>
    <visual>
      <origin xyz="0.0 0.0 0.0" rpy="0.0 0.0 0.0"/>
      <geometry>
        <box size="0.001 0.001 0.001"/>
      </geometry>
      <material name="light_grey"/>
    </visual>
  </link>
  <joint name="base_fixed" type="fixed">
    <origin xyz="-0.09199999999999665 0.08 0.091" rpy="0.0 -0.0 0.0"/>
    <parent link="base_link"/>
    <child link="link1"/>
  </joint>
</robot>